[2022-01-17 15:43:17,232] {taskinstance.py:903} INFO - Dependencies all met for <TaskInstance: example_dag.dbt_trigger 2022-01-17T15:42:44.945328+00:00 [queued]>
[2022-01-17 15:43:17,240] {taskinstance.py:903} INFO - Dependencies all met for <TaskInstance: example_dag.dbt_trigger 2022-01-17T15:42:44.945328+00:00 [queued]>
[2022-01-17 15:43:17,241] {taskinstance.py:1094} INFO - 
--------------------------------------------------------------------------------
[2022-01-17 15:43:17,241] {taskinstance.py:1095} INFO - Starting attempt 1 of 1
[2022-01-17 15:43:17,241] {taskinstance.py:1096} INFO - 
--------------------------------------------------------------------------------
[2022-01-17 15:43:17,259] {taskinstance.py:1114} INFO - Executing <Task(BashOperator): dbt_trigger> on 2022-01-17T15:42:44.945328+00:00
[2022-01-17 15:43:17,263] {standard_task_runner.py:52} INFO - Started process 184 to run task
[2022-01-17 15:43:17,268] {standard_task_runner.py:76} INFO - Running: ['***', 'tasks', 'run', 'example_dag', 'dbt_trigger', '2022-01-17T15:42:44.945328+00:00', '--job-id', '49', '--pool', 'default_pool', '--raw', '--subdir', 'DAGS_FOLDER/example_dag.py', '--cfg-path', '/tmp/tmpdse1xmih', '--error-file', '/tmp/tmpnxajibav']
[2022-01-17 15:43:17,269] {standard_task_runner.py:77} INFO - Job 49: Subtask dbt_trigger
[2022-01-17 15:43:17,325] {logging_mixin.py:109} INFO - Running <TaskInstance: example_dag.dbt_trigger 2022-01-17T15:42:44.945328+00:00 [running]> on host efd93b66773e
[2022-01-17 15:43:17,388] {taskinstance.py:1251} INFO - Exporting the following env vars:
AIRFLOW_CTX_DAG_OWNER=***
AIRFLOW_CTX_DAG_ID=example_dag
AIRFLOW_CTX_TASK_ID=dbt_trigger
AIRFLOW_CTX_EXECUTION_DATE=2022-01-17T15:42:44.945328+00:00
AIRFLOW_CTX_DAG_RUN_ID=manual__2022-01-17T15:42:44.945328+00:00
[2022-01-17 15:43:17,389] {subprocess.py:52} INFO - Tmp dir root location: 
 /tmp
[2022-01-17 15:43:17,390] {subprocess.py:63} INFO - Running command: ['bash', '-c', 'cd /home/dev/dbt && dbt run']
[2022-01-17 15:43:17,396] {subprocess.py:74} INFO - Output:
[2022-01-17 15:43:17,399] {subprocess.py:78} INFO - bash: line 0: cd: /home/dev/dbt: No such file or directory
[2022-01-17 15:43:17,399] {subprocess.py:82} INFO - Command exited with return code 1
[2022-01-17 15:43:17,410] {taskinstance.py:1462} ERROR - Task failed with exception
Traceback (most recent call last):
  File "/home/airflow/.local/lib/python3.8/site-packages/airflow/models/taskinstance.py", line 1164, in _run_raw_task
    self._prepare_and_execute_task_with_callbacks(context, task)
  File "/home/airflow/.local/lib/python3.8/site-packages/airflow/models/taskinstance.py", line 1282, in _prepare_and_execute_task_with_callbacks
    result = self._execute_task(context, task_copy)
  File "/home/airflow/.local/lib/python3.8/site-packages/airflow/models/taskinstance.py", line 1312, in _execute_task
    result = task_copy.execute(context=context)
  File "/home/airflow/.local/lib/python3.8/site-packages/airflow/operators/bash.py", line 176, in execute
    raise AirflowException('Bash command failed. The command returned a non-zero exit code.')
airflow.exceptions.AirflowException: Bash command failed. The command returned a non-zero exit code.
[2022-01-17 15:43:17,411] {taskinstance.py:1505} INFO - Marking task as FAILED. dag_id=example_dag, task_id=dbt_trigger, execution_date=20220117T154244, start_date=20220117T154317, end_date=20220117T154317
[2022-01-17 15:43:17,438] {local_task_job.py:151} INFO - Task exited with return code 1
[2022-01-17 15:43:17,458] {local_task_job.py:261} INFO - 0 downstream tasks scheduled from follow-on schedule check
