[2022-01-20 00:00:42,147] {taskinstance.py:903} INFO - Dependencies all met for <TaskInstance: example_dag.dbt_trigger 2022-01-19T00:00:00+00:00 [queued]>
[2022-01-20 00:00:42,159] {taskinstance.py:903} INFO - Dependencies all met for <TaskInstance: example_dag.dbt_trigger 2022-01-19T00:00:00+00:00 [queued]>
[2022-01-20 00:00:42,159] {taskinstance.py:1094} INFO - 
--------------------------------------------------------------------------------
[2022-01-20 00:00:42,160] {taskinstance.py:1095} INFO - Starting attempt 1 of 1
[2022-01-20 00:00:42,160] {taskinstance.py:1096} INFO - 
--------------------------------------------------------------------------------
[2022-01-20 00:00:42,204] {taskinstance.py:1114} INFO - Executing <Task(BashOperator): dbt_trigger> on 2022-01-19T00:00:00+00:00
[2022-01-20 00:00:42,208] {standard_task_runner.py:52} INFO - Started process 16656 to run task
[2022-01-20 00:00:42,216] {standard_task_runner.py:76} INFO - Running: ['***', 'tasks', 'run', 'example_dag', 'dbt_trigger', '2022-01-19T00:00:00+00:00', '--job-id', '1273', '--pool', 'default_pool', '--raw', '--subdir', 'DAGS_FOLDER/example_dag.py', '--cfg-path', '/tmp/tmpsjzdqioi', '--error-file', '/tmp/tmps0m24w7t']
[2022-01-20 00:00:42,218] {standard_task_runner.py:77} INFO - Job 1273: Subtask dbt_trigger
[2022-01-20 00:00:42,298] {logging_mixin.py:109} INFO - Running <TaskInstance: example_dag.dbt_trigger 2022-01-19T00:00:00+00:00 [running]> on host c7f08ec3c7e5
[2022-01-20 00:00:42,406] {taskinstance.py:1251} INFO - Exporting the following env vars:
AIRFLOW_CTX_DAG_OWNER=***
AIRFLOW_CTX_DAG_ID=example_dag
AIRFLOW_CTX_TASK_ID=dbt_trigger
AIRFLOW_CTX_EXECUTION_DATE=2022-01-19T00:00:00+00:00
AIRFLOW_CTX_DAG_RUN_ID=scheduled__2022-01-19T00:00:00+00:00
[2022-01-20 00:00:42,407] {subprocess.py:52} INFO - Tmp dir root location: 
 /tmp
[2022-01-20 00:00:42,408] {subprocess.py:63} INFO - Running command: ['bash', '-c', 'cd /home/dev && ls']
[2022-01-20 00:00:42,419] {subprocess.py:74} INFO - Output:
[2022-01-20 00:00:42,426] {subprocess.py:78} INFO - bash: line 0: cd: /home/dev: No such file or directory
[2022-01-20 00:00:42,426] {subprocess.py:82} INFO - Command exited with return code 1
[2022-01-20 00:00:42,443] {taskinstance.py:1462} ERROR - Task failed with exception
Traceback (most recent call last):
  File "/home/airflow/.local/lib/python3.8/site-packages/airflow/models/taskinstance.py", line 1164, in _run_raw_task
    self._prepare_and_execute_task_with_callbacks(context, task)
  File "/home/airflow/.local/lib/python3.8/site-packages/airflow/models/taskinstance.py", line 1282, in _prepare_and_execute_task_with_callbacks
    result = self._execute_task(context, task_copy)
  File "/home/airflow/.local/lib/python3.8/site-packages/airflow/models/taskinstance.py", line 1312, in _execute_task
    result = task_copy.execute(context=context)
  File "/home/airflow/.local/lib/python3.8/site-packages/airflow/operators/bash.py", line 176, in execute
    raise AirflowException('Bash command failed. The command returned a non-zero exit code.')
airflow.exceptions.AirflowException: Bash command failed. The command returned a non-zero exit code.
[2022-01-20 00:00:42,445] {taskinstance.py:1505} INFO - Marking task as FAILED. dag_id=example_dag, task_id=dbt_trigger, execution_date=20220119T000000, start_date=20220120T000042, end_date=20220120T000042
[2022-01-20 00:00:42,480] {local_task_job.py:151} INFO - Task exited with return code 1
[2022-01-20 00:00:42,522] {local_task_job.py:261} INFO - 0 downstream tasks scheduled from follow-on schedule check
