[2022-01-17 17:32:22,169] {taskinstance.py:903} INFO - Dependencies all met for <TaskInstance: dbt_dag.dbt_run 2022-01-17T17:32:20.323901+00:00 [queued]>
[2022-01-17 17:32:22,184] {taskinstance.py:903} INFO - Dependencies all met for <TaskInstance: dbt_dag.dbt_run 2022-01-17T17:32:20.323901+00:00 [queued]>
[2022-01-17 17:32:22,185] {taskinstance.py:1094} INFO - 
--------------------------------------------------------------------------------
[2022-01-17 17:32:22,185] {taskinstance.py:1095} INFO - Starting attempt 1 of 1
[2022-01-17 17:32:22,185] {taskinstance.py:1096} INFO - 
--------------------------------------------------------------------------------
[2022-01-17 17:32:22,205] {taskinstance.py:1114} INFO - Executing <Task(BashOperator): dbt_run> on 2022-01-17T17:32:20.323901+00:00
[2022-01-17 17:32:22,210] {standard_task_runner.py:52} INFO - Started process 563 to run task
[2022-01-17 17:32:22,215] {standard_task_runner.py:76} INFO - Running: ['***', 'tasks', 'run', 'dbt_dag', 'dbt_run', '2022-01-17T17:32:20.323901+00:00', '--job-id', '102', '--pool', 'default_pool', '--raw', '--subdir', 'DAGS_FOLDER/dbt_example.py', '--cfg-path', '/tmp/tmpmz02iwd7', '--error-file', '/tmp/tmpbcy13ezf']
[2022-01-17 17:32:22,216] {standard_task_runner.py:77} INFO - Job 102: Subtask dbt_run
[2022-01-17 17:32:22,296] {logging_mixin.py:109} INFO - Running <TaskInstance: dbt_dag.dbt_run 2022-01-17T17:32:20.323901+00:00 [running]> on host efd93b66773e
[2022-01-17 17:32:22,378] {taskinstance.py:1251} INFO - Exporting the following env vars:
AIRFLOW_CTX_DAG_OWNER=***
AIRFLOW_CTX_DAG_ID=dbt_dag
AIRFLOW_CTX_TASK_ID=dbt_run
AIRFLOW_CTX_EXECUTION_DATE=2022-01-17T17:32:20.323901+00:00
AIRFLOW_CTX_DAG_RUN_ID=manual__2022-01-17T17:32:20.323901+00:00
[2022-01-17 17:32:22,379] {subprocess.py:52} INFO - Tmp dir root location: 
 /tmp
[2022-01-17 17:32:22,379] {subprocess.py:63} INFO - Running command: ['bash', '-c', 'dbt run']
[2022-01-17 17:32:22,390] {subprocess.py:74} INFO - Output:
[2022-01-17 17:32:22,391] {subprocess.py:78} INFO - bash: dbt: command not found
[2022-01-17 17:32:22,392] {subprocess.py:82} INFO - Command exited with return code 127
[2022-01-17 17:32:22,410] {taskinstance.py:1462} ERROR - Task failed with exception
Traceback (most recent call last):
  File "/home/airflow/.local/lib/python3.8/site-packages/airflow/models/taskinstance.py", line 1164, in _run_raw_task
    self._prepare_and_execute_task_with_callbacks(context, task)
  File "/home/airflow/.local/lib/python3.8/site-packages/airflow/models/taskinstance.py", line 1282, in _prepare_and_execute_task_with_callbacks
    result = self._execute_task(context, task_copy)
  File "/home/airflow/.local/lib/python3.8/site-packages/airflow/models/taskinstance.py", line 1312, in _execute_task
    result = task_copy.execute(context=context)
  File "/home/airflow/.local/lib/python3.8/site-packages/airflow/operators/bash.py", line 176, in execute
    raise AirflowException('Bash command failed. The command returned a non-zero exit code.')
airflow.exceptions.AirflowException: Bash command failed. The command returned a non-zero exit code.
[2022-01-17 17:32:22,412] {taskinstance.py:1505} INFO - Marking task as FAILED. dag_id=dbt_dag, task_id=dbt_run, execution_date=20220117T173220, start_date=20220117T173222, end_date=20220117T173222
[2022-01-17 17:32:22,477] {local_task_job.py:151} INFO - Task exited with return code 1
[2022-01-17 17:32:22,519] {local_task_job.py:261} INFO - 0 downstream tasks scheduled from follow-on schedule check
