[2022-01-17 17:32:07,864] {taskinstance.py:903} INFO - Dependencies all met for <TaskInstance: dbt_dag.dbt_run 2021-12-26T00:00:00+00:00 [queued]>
[2022-01-17 17:32:07,902] {taskinstance.py:903} INFO - Dependencies all met for <TaskInstance: dbt_dag.dbt_run 2021-12-26T00:00:00+00:00 [queued]>
[2022-01-17 17:32:07,903] {taskinstance.py:1094} INFO - 
--------------------------------------------------------------------------------
[2022-01-17 17:32:07,903] {taskinstance.py:1095} INFO - Starting attempt 1 of 1
[2022-01-17 17:32:07,903] {taskinstance.py:1096} INFO - 
--------------------------------------------------------------------------------
[2022-01-17 17:32:08,000] {taskinstance.py:1114} INFO - Executing <Task(BashOperator): dbt_run> on 2021-12-26T00:00:00+00:00
[2022-01-17 17:32:08,026] {standard_task_runner.py:52} INFO - Started process 488 to run task
[2022-01-17 17:32:08,050] {standard_task_runner.py:76} INFO - Running: ['***', 'tasks', 'run', 'dbt_dag', 'dbt_run', '2021-12-26T00:00:00+00:00', '--job-id', '80', '--pool', 'default_pool', '--raw', '--subdir', 'DAGS_FOLDER/dbt_example.py', '--cfg-path', '/tmp/tmp5x2lyb3h', '--error-file', '/tmp/tmpre6nv692']
[2022-01-17 17:32:08,054] {standard_task_runner.py:77} INFO - Job 80: Subtask dbt_run
[2022-01-17 17:32:08,289] {logging_mixin.py:109} INFO - Running <TaskInstance: dbt_dag.dbt_run 2021-12-26T00:00:00+00:00 [running]> on host efd93b66773e
[2022-01-17 17:32:08,509] {taskinstance.py:1251} INFO - Exporting the following env vars:
AIRFLOW_CTX_DAG_OWNER=***
AIRFLOW_CTX_DAG_ID=dbt_dag
AIRFLOW_CTX_TASK_ID=dbt_run
AIRFLOW_CTX_EXECUTION_DATE=2021-12-26T00:00:00+00:00
AIRFLOW_CTX_DAG_RUN_ID=scheduled__2021-12-26T00:00:00+00:00
[2022-01-17 17:32:08,509] {subprocess.py:52} INFO - Tmp dir root location: 
 /tmp
[2022-01-17 17:32:08,510] {subprocess.py:63} INFO - Running command: ['bash', '-c', 'dbt run']
[2022-01-17 17:32:08,531] {subprocess.py:74} INFO - Output:
[2022-01-17 17:32:08,532] {subprocess.py:78} INFO - bash: dbt: command not found
[2022-01-17 17:32:08,532] {subprocess.py:82} INFO - Command exited with return code 127
[2022-01-17 17:32:08,595] {taskinstance.py:1462} ERROR - Task failed with exception
Traceback (most recent call last):
  File "/home/airflow/.local/lib/python3.8/site-packages/airflow/models/taskinstance.py", line 1164, in _run_raw_task
    self._prepare_and_execute_task_with_callbacks(context, task)
  File "/home/airflow/.local/lib/python3.8/site-packages/airflow/models/taskinstance.py", line 1282, in _prepare_and_execute_task_with_callbacks
    result = self._execute_task(context, task_copy)
  File "/home/airflow/.local/lib/python3.8/site-packages/airflow/models/taskinstance.py", line 1312, in _execute_task
    result = task_copy.execute(context=context)
  File "/home/airflow/.local/lib/python3.8/site-packages/airflow/operators/bash.py", line 176, in execute
    raise AirflowException('Bash command failed. The command returned a non-zero exit code.')
airflow.exceptions.AirflowException: Bash command failed. The command returned a non-zero exit code.
[2022-01-17 17:32:08,597] {taskinstance.py:1505} INFO - Marking task as FAILED. dag_id=dbt_dag, task_id=dbt_run, execution_date=20211226T000000, start_date=20220117T173207, end_date=20220117T173208
[2022-01-17 17:32:08,734] {local_task_job.py:151} INFO - Task exited with return code 1
[2022-01-17 17:32:08,799] {local_task_job.py:261} INFO - 0 downstream tasks scheduled from follow-on schedule check
