[2022-01-17 18:08:58,284] {taskinstance.py:903} INFO - Dependencies all met for <TaskInstance: dbt_dag_ex.dbt_trigger 2022-01-17T18:08:57.895059+00:00 [queued]>
[2022-01-17 18:08:58,293] {taskinstance.py:903} INFO - Dependencies all met for <TaskInstance: dbt_dag_ex.dbt_trigger 2022-01-17T18:08:57.895059+00:00 [queued]>
[2022-01-17 18:08:58,293] {taskinstance.py:1094} INFO - 
--------------------------------------------------------------------------------
[2022-01-17 18:08:58,293] {taskinstance.py:1095} INFO - Starting attempt 1 of 1
[2022-01-17 18:08:58,293] {taskinstance.py:1096} INFO - 
--------------------------------------------------------------------------------
[2022-01-17 18:08:58,313] {taskinstance.py:1114} INFO - Executing <Task(BashOperator): dbt_trigger> on 2022-01-17T18:08:57.895059+00:00
[2022-01-17 18:08:58,317] {standard_task_runner.py:52} INFO - Started process 186 to run task
[2022-01-17 18:08:58,322] {standard_task_runner.py:76} INFO - Running: ['***', 'tasks', 'run', 'dbt_dag_ex', 'dbt_trigger', '2022-01-17T18:08:57.895059+00:00', '--job-id', '107', '--pool', 'default_pool', '--raw', '--subdir', 'DAGS_FOLDER/dbt_example.py', '--cfg-path', '/tmp/tmpsm9jrn0r', '--error-file', '/tmp/tmp18ehx858']
[2022-01-17 18:08:58,323] {standard_task_runner.py:77} INFO - Job 107: Subtask dbt_trigger
[2022-01-17 18:08:58,385] {logging_mixin.py:109} INFO - Running <TaskInstance: dbt_dag_ex.dbt_trigger 2022-01-17T18:08:57.895059+00:00 [running]> on host 0ec4d6d8cdee
[2022-01-17 18:08:58,450] {taskinstance.py:1251} INFO - Exporting the following env vars:
AIRFLOW_CTX_DAG_OWNER=***
AIRFLOW_CTX_DAG_ID=dbt_dag_ex
AIRFLOW_CTX_TASK_ID=dbt_trigger
AIRFLOW_CTX_EXECUTION_DATE=2022-01-17T18:08:57.895059+00:00
AIRFLOW_CTX_DAG_RUN_ID=manual__2022-01-17T18:08:57.895059+00:00
[2022-01-17 18:08:58,450] {subprocess.py:52} INFO - Tmp dir root location: 
 /tmp
[2022-01-17 18:08:58,451] {subprocess.py:63} INFO - Running command: ['bash', '-c', 'dbt run']
[2022-01-17 18:08:58,465] {subprocess.py:74} INFO - Output:
[2022-01-17 18:08:58,469] {subprocess.py:78} INFO - bash: dbt: command not found
[2022-01-17 18:08:58,470] {subprocess.py:82} INFO - Command exited with return code 127
[2022-01-17 18:08:58,495] {taskinstance.py:1462} ERROR - Task failed with exception
Traceback (most recent call last):
  File "/home/airflow/.local/lib/python3.8/site-packages/airflow/models/taskinstance.py", line 1164, in _run_raw_task
    self._prepare_and_execute_task_with_callbacks(context, task)
  File "/home/airflow/.local/lib/python3.8/site-packages/airflow/models/taskinstance.py", line 1282, in _prepare_and_execute_task_with_callbacks
    result = self._execute_task(context, task_copy)
  File "/home/airflow/.local/lib/python3.8/site-packages/airflow/models/taskinstance.py", line 1312, in _execute_task
    result = task_copy.execute(context=context)
  File "/home/airflow/.local/lib/python3.8/site-packages/airflow/operators/bash.py", line 176, in execute
    raise AirflowException('Bash command failed. The command returned a non-zero exit code.')
airflow.exceptions.AirflowException: Bash command failed. The command returned a non-zero exit code.
[2022-01-17 18:08:58,497] {taskinstance.py:1505} INFO - Marking task as FAILED. dag_id=dbt_dag_ex, task_id=dbt_trigger, execution_date=20220117T180857, start_date=20220117T180858, end_date=20220117T180858
[2022-01-17 18:08:58,542] {local_task_job.py:151} INFO - Task exited with return code 1
[2022-01-17 18:08:58,573] {local_task_job.py:261} INFO - 0 downstream tasks scheduled from follow-on schedule check
